<?xml version="1.0"?>
<robot xmlns:xacro="http://www.ros.org/wiki/xacro">

    <xacro:include filename="inertial_macros.xacro"/>

    <material name="black">
        <color rgba="0 0 0 1"/>
    </material>
    
    <material name="yellow">
        <color rgba="1 1 0 1"/>
    </material>

    <material name="gray">
        <color rgba="0.5 0.5 0.5 1"/>
    </material>

    <material name="blue">
        <color rgba="0 0 1 1"/>
    </material>

    <material name="olive">
        <color rgba="0.5 0.5 0 1"/>
    </material>

    <!-- base_link -->
    <link name="base_link">
    </link>

    <!-- chassis -->
    <joint name="chassis_joint" type="fixed">
        <parent link="base_link"/>
        <child link="chassis_link"/>
        <origin xyz="-0.1 0 0"/>
    </joint>

    <link name="chassis_link">
        <visual>
            <geometry>
                <box size="0.32 0.22 0.10"/>
            </geometry>
            <material name="black"/>
            <origin xyz="0.16 0 0.050" rpy="0 0 0"/>
        </visual>
        <collision>
            <geometry>
                <box size="0.32 0.22 0.10"/>
            </geometry>
            <origin xyz="0.16 0 0.050" rpy="0 0 0"/>
        </collision>
        <xacro:inertial_box mass="1" x="0.32" y="0.22" z="0.10">
            <origin xyz="0.16 0 0.050" rpy="0 0 0"/>
        </xacro:inertial_box>
    </link>

    <gazebo reference="chassis_link">
        <material>Gazebo/Black</material>
    </gazebo>

    <!--Macro Wheel-->
    <xacro:macro name="wheel_link" params="prefix place">
        <link name="${prefix}_wheel_${place}_link">
            <visual>
                <geometry>
                    <cylinder radius="0.035" length="0.025" />
                </geometry>
                <material name="yellow" />
            </visual>
            <collision>
                <geometry>
                    <cylinder radius="0.035" length="0.025" />
                </geometry>
                <origin xyz="0 0 0" rpy="0 0 0" />
            </collision>
            <xacro:inertial_cylinder mass="0.2" length="0.025" radius="0.035">
                <origin xyz="0 0 0" rpy="0 0 0" />
            </xacro:inertial_cylinder>
        </link>

        <gazebo reference="${prefix}_wheel_${place}_link">
            <material>Gazebo/Yellow</material>
        </gazebo>
    </xacro:macro>

    <!--Left Wheel Front-->
    <joint name="left_wheel_front_joint" type="continuous">
        <parent link="base_link" />
        <child link="left_wheel_front_link" />
        <origin xyz="0.14 0.122 0" rpy="${pi/2} 0 0" />
        <axis xyz="0 0 1" />
    </joint>

    <xacro:wheel_link prefix="left" place="front" />

    <!--Left Wheel back-->
    <joint name="left_wheel_back_joint" type="continuous">
        <parent link="base_link" />
        <child link="left_wheel_back_link" />
        <origin xyz="-0.02 0.122 0" rpy="${pi/2} 0 0" />
        <axis xyz="0 0 1" />
    </joint>

    <xacro:wheel_link prefix="left" place="back" />

    <!--Right Wheel Front-->
    <joint name="right_wheel_front_joint" type="continuous">
        <parent link="base_link" />
        <child link="right_wheel_front_link" />
        <origin xyz="0.14 -0.122 0" rpy="${pi/2} 0 0" />
        <axis xyz="0 0 -1" />
    </joint>

    <xacro:wheel_link prefix="right" place="front" />

    <!--Right Wheel Back-->
    <joint name="right_wheel_back_joint" type="continuous">
        <parent link="base_link" />
        <child link="right_wheel_back_link" />
        <origin xyz="-0.02 -0.122 0" rpy="${pi/2} 0 0" />
        <axis xyz="0 0 -1" />
    </joint>

    <xacro:wheel_link prefix="right" place="back" />

</robot>